[2024-05-10T00:00:32.467+0000] {processor.py:161} INFO - Started process (PID=25001) to work on /home/airflow/.local/lib/python3.12/site-packages/airflow/example_dags/example_sla_dag.py
[2024-05-10T00:00:32.472+0000] {processor.py:830} INFO - Processing file /home/airflow/.local/lib/python3.12/site-packages/airflow/example_dags/example_sla_dag.py for tasks to queue
[2024-05-10T00:00:32.479+0000] {logging_mixin.py:188} INFO - [2024-05-10T00:00:32.479+0000] {dagbag.py:545} INFO - Filling up the DagBag from /home/airflow/.local/lib/python3.12/site-packages/airflow/example_dags/example_sla_dag.py
[2024-05-10T00:00:32.497+0000] {processor.py:840} INFO - DAG(s) 'example_sla_dag' retrieved from /home/airflow/.local/lib/python3.12/site-packages/airflow/example_dags/example_sla_dag.py
[2024-05-10T00:00:32.537+0000] {logging_mixin.py:188} INFO - [2024-05-10T00:00:32.537+0000] {dag.py:3096} INFO - Sync 1 DAGs
[2024-05-10T00:00:32.602+0000] {logging_mixin.py:188} INFO - [2024-05-10T00:00:32.602+0000] {dag.py:3954} INFO - Setting next_dagrun for example_sla_dag to 2024-05-09 23:58:00+00:00, run_after=2024-05-10 00:00:00+00:00
[2024-05-10T00:00:32.645+0000] {processor.py:183} INFO - Processing /home/airflow/.local/lib/python3.12/site-packages/airflow/example_dags/example_sla_dag.py took 0.189 seconds
[2024-05-10T00:01:03.373+0000] {processor.py:161} INFO - Started process (PID=25059) to work on /home/airflow/.local/lib/python3.12/site-packages/airflow/example_dags/example_sla_dag.py
[2024-05-10T00:01:03.377+0000] {processor.py:830} INFO - Processing file /home/airflow/.local/lib/python3.12/site-packages/airflow/example_dags/example_sla_dag.py for tasks to queue
[2024-05-10T00:01:03.382+0000] {logging_mixin.py:188} INFO - [2024-05-10T00:01:03.382+0000] {dagbag.py:545} INFO - Filling up the DagBag from /home/airflow/.local/lib/python3.12/site-packages/airflow/example_dags/example_sla_dag.py
[2024-05-10T00:01:03.399+0000] {processor.py:840} INFO - DAG(s) 'example_sla_dag' retrieved from /home/airflow/.local/lib/python3.12/site-packages/airflow/example_dags/example_sla_dag.py
[2024-05-10T00:01:03.458+0000] {logging_mixin.py:188} INFO - [2024-05-10T00:01:03.457+0000] {dag.py:3096} INFO - Sync 1 DAGs
[2024-05-10T00:01:03.509+0000] {logging_mixin.py:188} INFO - [2024-05-10T00:01:03.509+0000] {dag.py:3954} INFO - Setting next_dagrun for example_sla_dag to 2024-05-09 23:58:00+00:00, run_after=2024-05-10 00:00:00+00:00
[2024-05-10T00:01:03.543+0000] {processor.py:183} INFO - Processing /home/airflow/.local/lib/python3.12/site-packages/airflow/example_dags/example_sla_dag.py took 0.182 seconds
[2024-05-10T00:01:34.358+0000] {processor.py:161} INFO - Started process (PID=25117) to work on /home/airflow/.local/lib/python3.12/site-packages/airflow/example_dags/example_sla_dag.py
[2024-05-10T00:01:34.361+0000] {processor.py:830} INFO - Processing file /home/airflow/.local/lib/python3.12/site-packages/airflow/example_dags/example_sla_dag.py for tasks to queue
[2024-05-10T00:01:34.364+0000] {logging_mixin.py:188} INFO - [2024-05-10T00:01:34.364+0000] {dagbag.py:545} INFO - Filling up the DagBag from /home/airflow/.local/lib/python3.12/site-packages/airflow/example_dags/example_sla_dag.py
[2024-05-10T00:01:34.378+0000] {processor.py:840} INFO - DAG(s) 'example_sla_dag' retrieved from /home/airflow/.local/lib/python3.12/site-packages/airflow/example_dags/example_sla_dag.py
[2024-05-10T00:01:34.406+0000] {logging_mixin.py:188} INFO - [2024-05-10T00:01:34.406+0000] {dag.py:3096} INFO - Sync 1 DAGs
[2024-05-10T00:01:34.431+0000] {logging_mixin.py:188} INFO - [2024-05-10T00:01:34.431+0000] {dag.py:3954} INFO - Setting next_dagrun for example_sla_dag to 2024-05-09 23:58:00+00:00, run_after=2024-05-10 00:00:00+00:00
[2024-05-10T00:01:34.455+0000] {processor.py:183} INFO - Processing /home/airflow/.local/lib/python3.12/site-packages/airflow/example_dags/example_sla_dag.py took 0.104 seconds
[2024-05-10T00:02:09.021+0000] {processor.py:161} INFO - Started process (PID=25174) to work on /home/airflow/.local/lib/python3.12/site-packages/airflow/example_dags/example_sla_dag.py
[2024-05-10T00:02:09.030+0000] {processor.py:830} INFO - Processing file /home/airflow/.local/lib/python3.12/site-packages/airflow/example_dags/example_sla_dag.py for tasks to queue
[2024-05-10T00:02:09.035+0000] {logging_mixin.py:188} INFO - [2024-05-10T00:02:09.035+0000] {dagbag.py:545} INFO - Filling up the DagBag from /home/airflow/.local/lib/python3.12/site-packages/airflow/example_dags/example_sla_dag.py
[2024-05-10T00:02:09.056+0000] {processor.py:840} INFO - DAG(s) 'example_sla_dag' retrieved from /home/airflow/.local/lib/python3.12/site-packages/airflow/example_dags/example_sla_dag.py
[2024-05-10T00:02:09.103+0000] {logging_mixin.py:188} INFO - [2024-05-10T00:02:09.102+0000] {dag.py:3096} INFO - Sync 1 DAGs
[2024-05-10T00:02:09.148+0000] {logging_mixin.py:188} INFO - [2024-05-10T00:02:09.148+0000] {dag.py:3954} INFO - Setting next_dagrun for example_sla_dag to 2024-05-10 00:00:00+00:00, run_after=2024-05-10 00:02:00+00:00
[2024-05-10T00:02:09.196+0000] {processor.py:183} INFO - Processing /home/airflow/.local/lib/python3.12/site-packages/airflow/example_dags/example_sla_dag.py took 0.184 seconds
[2024-05-10T00:02:39.384+0000] {processor.py:161} INFO - Started process (PID=25231) to work on /home/airflow/.local/lib/python3.12/site-packages/airflow/example_dags/example_sla_dag.py
[2024-05-10T00:02:39.390+0000] {processor.py:830} INFO - Processing file /home/airflow/.local/lib/python3.12/site-packages/airflow/example_dags/example_sla_dag.py for tasks to queue
[2024-05-10T00:02:39.406+0000] {logging_mixin.py:188} INFO - [2024-05-10T00:02:39.404+0000] {dagbag.py:545} INFO - Filling up the DagBag from /home/airflow/.local/lib/python3.12/site-packages/airflow/example_dags/example_sla_dag.py
[2024-05-10T00:02:39.423+0000] {processor.py:840} INFO - DAG(s) 'example_sla_dag' retrieved from /home/airflow/.local/lib/python3.12/site-packages/airflow/example_dags/example_sla_dag.py
[2024-05-10T00:02:39.453+0000] {logging_mixin.py:188} INFO - [2024-05-10T00:02:39.453+0000] {dag.py:3096} INFO - Sync 1 DAGs
[2024-05-10T00:02:39.487+0000] {logging_mixin.py:188} INFO - [2024-05-10T00:02:39.487+0000] {dag.py:3954} INFO - Setting next_dagrun for example_sla_dag to 2024-05-10 00:00:00+00:00, run_after=2024-05-10 00:02:00+00:00
[2024-05-10T00:02:39.542+0000] {processor.py:183} INFO - Processing /home/airflow/.local/lib/python3.12/site-packages/airflow/example_dags/example_sla_dag.py took 0.173 seconds
[2024-05-10T00:03:13.465+0000] {processor.py:161} INFO - Started process (PID=25290) to work on /home/airflow/.local/lib/python3.12/site-packages/airflow/example_dags/example_sla_dag.py
[2024-05-10T00:03:13.470+0000] {processor.py:830} INFO - Processing file /home/airflow/.local/lib/python3.12/site-packages/airflow/example_dags/example_sla_dag.py for tasks to queue
[2024-05-10T00:03:13.476+0000] {logging_mixin.py:188} INFO - [2024-05-10T00:03:13.475+0000] {dagbag.py:545} INFO - Filling up the DagBag from /home/airflow/.local/lib/python3.12/site-packages/airflow/example_dags/example_sla_dag.py
[2024-05-10T00:03:13.500+0000] {processor.py:840} INFO - DAG(s) 'example_sla_dag' retrieved from /home/airflow/.local/lib/python3.12/site-packages/airflow/example_dags/example_sla_dag.py
[2024-05-10T00:03:13.644+0000] {logging_mixin.py:188} INFO - [2024-05-10T00:03:13.643+0000] {dag.py:3096} INFO - Sync 1 DAGs
[2024-05-10T00:03:14.286+0000] {processor.py:186} ERROR - Got an exception! Propagating...
Traceback (most recent call last):
  File "/home/airflow/.local/lib/python3.12/site-packages/sqlalchemy/engine/base.py", line 3371, in _wrap_pool_connect
    return fn()
           ^^^^
  File "/home/airflow/.local/lib/python3.12/site-packages/sqlalchemy/pool/base.py", line 327, in connect
    return _ConnectionFairy._checkout(self)
           ^^^^^^^^^^^^^^^^^^^^^^^^^^^^^^^^
  File "/home/airflow/.local/lib/python3.12/site-packages/sqlalchemy/pool/base.py", line 894, in _checkout
    fairy = _ConnectionRecord.checkout(pool)
            ^^^^^^^^^^^^^^^^^^^^^^^^^^^^^^^^
  File "/home/airflow/.local/lib/python3.12/site-packages/sqlalchemy/pool/base.py", line 497, in checkout
    with util.safe_reraise():
  File "/home/airflow/.local/lib/python3.12/site-packages/sqlalchemy/util/langhelpers.py", line 70, in __exit__
    compat.raise_(
  File "/home/airflow/.local/lib/python3.12/site-packages/sqlalchemy/util/compat.py", line 211, in raise_
    raise exception
  File "/home/airflow/.local/lib/python3.12/site-packages/sqlalchemy/pool/base.py", line 495, in checkout
    dbapi_connection = rec.get_connection()
                       ^^^^^^^^^^^^^^^^^^^^
  File "/home/airflow/.local/lib/python3.12/site-packages/sqlalchemy/pool/base.py", line 630, in get_connection
    self.__connect()
  File "/home/airflow/.local/lib/python3.12/site-packages/sqlalchemy/pool/base.py", line 690, in __connect
    with util.safe_reraise():
  File "/home/airflow/.local/lib/python3.12/site-packages/sqlalchemy/util/langhelpers.py", line 70, in __exit__
    compat.raise_(
  File "/home/airflow/.local/lib/python3.12/site-packages/sqlalchemy/util/compat.py", line 211, in raise_
    raise exception
  File "/home/airflow/.local/lib/python3.12/site-packages/sqlalchemy/pool/base.py", line 686, in __connect
    self.dbapi_connection = connection = pool._invoke_creator(self)
                                         ^^^^^^^^^^^^^^^^^^^^^^^^^^
  File "/home/airflow/.local/lib/python3.12/site-packages/sqlalchemy/engine/create.py", line 574, in connect
    return dialect.connect(*cargs, **cparams)
           ^^^^^^^^^^^^^^^^^^^^^^^^^^^^^^^^^^
  File "/home/airflow/.local/lib/python3.12/site-packages/sqlalchemy/engine/default.py", line 598, in connect
    return self.dbapi.connect(*cargs, **cparams)
           ^^^^^^^^^^^^^^^^^^^^^^^^^^^^^^^^^^^^^
  File "/home/airflow/.local/lib/python3.12/site-packages/psycopg2/__init__.py", line 122, in connect
    conn = _connect(dsn, connection_factory=connection_factory, **kwasync)
           ^^^^^^^^^^^^^^^^^^^^^^^^^^^^^^^^^^^^^^^^^^^^^^^^^^^^^^^^^^^^^^^
psycopg2.OperationalError: connection to server at "postgres" (172.18.0.3), port 5432 failed: Connection refused
	Is the server running on that host and accepting TCP/IP connections?


The above exception was the direct cause of the following exception:

Traceback (most recent call last):
  File "/home/airflow/.local/lib/python3.12/site-packages/airflow/dag_processing/processor.py", line 182, in _run_file_processor
    _handle_dag_file_processing()
  File "/home/airflow/.local/lib/python3.12/site-packages/airflow/dag_processing/processor.py", line 163, in _handle_dag_file_processing
    result: tuple[int, int] = dag_file_processor.process_file(
                              ^^^^^^^^^^^^^^^^^^^^^^^^^^^^^^^^
  File "/home/airflow/.local/lib/python3.12/site-packages/airflow/utils/session.py", line 79, in wrapper
    return func(*args, session=session, **kwargs)
           ^^^^^^^^^^^^^^^^^^^^^^^^^^^^^^^^^^^^^^
  File "/home/airflow/.local/lib/python3.12/site-packages/airflow/dag_processing/processor.py", line 859, in process_file
    serialize_errors = DagFileProcessor.save_dag_to_db(
                       ^^^^^^^^^^^^^^^^^^^^^^^^^^^^^^^^
  File "/home/airflow/.local/lib/python3.12/site-packages/airflow/api_internal/internal_api_call.py", line 115, in wrapper
    return func(*args, **kwargs)
           ^^^^^^^^^^^^^^^^^^^^^
  File "/home/airflow/.local/lib/python3.12/site-packages/airflow/utils/session.py", line 79, in wrapper
    return func(*args, session=session, **kwargs)
           ^^^^^^^^^^^^^^^^^^^^^^^^^^^^^^^^^^^^^^
  File "/home/airflow/.local/lib/python3.12/site-packages/airflow/dag_processing/processor.py", line 895, in save_dag_to_db
    import_errors = DagBag._sync_to_db(dags=dags, processor_subdir=dag_directory, session=session)
                    ^^^^^^^^^^^^^^^^^^^^^^^^^^^^^^^^^^^^^^^^^^^^^^^^^^^^^^^^^^^^^^^^^^^^^^^^^^^^^^
  File "/home/airflow/.local/lib/python3.12/site-packages/airflow/utils/session.py", line 76, in wrapper
    return func(*args, **kwargs)
           ^^^^^^^^^^^^^^^^^^^^^
  File "/home/airflow/.local/lib/python3.12/site-packages/airflow/models/dagbag.py", line 664, in _sync_to_db
    for attempt in run_with_db_retries(logger=log):
  File "/home/airflow/.local/lib/python3.12/site-packages/tenacity/__init__.py", line 347, in __iter__
    do = self.iter(retry_state=retry_state)
         ^^^^^^^^^^^^^^^^^^^^^^^^^^^^^^^^^^
  File "/home/airflow/.local/lib/python3.12/site-packages/tenacity/__init__.py", line 325, in iter
    raise retry_exc.reraise()
          ^^^^^^^^^^^^^^^^^^^
  File "/home/airflow/.local/lib/python3.12/site-packages/tenacity/__init__.py", line 158, in reraise
    raise self.last_attempt.result()
          ^^^^^^^^^^^^^^^^^^^^^^^^^^
  File "/usr/local/lib/python3.12/concurrent/futures/_base.py", line 449, in result
    return self.__get_result()
           ^^^^^^^^^^^^^^^^^^^
  File "/usr/local/lib/python3.12/concurrent/futures/_base.py", line 401, in __get_result
    raise self._exception
  File "/home/airflow/.local/lib/python3.12/site-packages/airflow/models/dagbag.py", line 677, in _sync_to_db
    _serialize_dag_capturing_errors(dag, session, processor_subdir)
  File "/home/airflow/.local/lib/python3.12/site-packages/airflow/models/dagbag.py", line 642, in _serialize_dag_capturing_errors
    dag_was_updated = SerializedDagModel.write_dag(
                      ^^^^^^^^^^^^^^^^^^^^^^^^^^^^^
  File "/home/airflow/.local/lib/python3.12/site-packages/airflow/utils/session.py", line 76, in wrapper
    return func(*args, **kwargs)
           ^^^^^^^^^^^^^^^^^^^^^
  File "/home/airflow/.local/lib/python3.12/site-packages/airflow/models/serialized_dag.py", line 158, in write_dag
    if session.scalar(
       ^^^^^^^^^^^^^^^
  File "/home/airflow/.local/lib/python3.12/site-packages/sqlalchemy/orm/session.py", line 1747, in scalar
    return self.execute(
           ^^^^^^^^^^^^^
  File "/home/airflow/.local/lib/python3.12/site-packages/sqlalchemy/orm/session.py", line 1716, in execute
    conn = self._connection_for_bind(bind)
           ^^^^^^^^^^^^^^^^^^^^^^^^^^^^^^^
  File "/home/airflow/.local/lib/python3.12/site-packages/sqlalchemy/orm/session.py", line 1555, in _connection_for_bind
    return self._transaction._connection_for_bind(
           ^^^^^^^^^^^^^^^^^^^^^^^^^^^^^^^^^^^^^^^
  File "/home/airflow/.local/lib/python3.12/site-packages/sqlalchemy/orm/session.py", line 750, in _connection_for_bind
    conn = bind.connect()
           ^^^^^^^^^^^^^^
  File "/home/airflow/.local/lib/python3.12/site-packages/sqlalchemy/future/engine.py", line 412, in connect
    return super(Engine, self).connect()
           ^^^^^^^^^^^^^^^^^^^^^^^^^^^^^
  File "/home/airflow/.local/lib/python3.12/site-packages/sqlalchemy/engine/base.py", line 3325, in connect
    return self._connection_cls(self, close_with_result=close_with_result)
           ^^^^^^^^^^^^^^^^^^^^^^^^^^^^^^^^^^^^^^^^^^^^^^^^^^^^^^^^^^^^^^^
  File "/home/airflow/.local/lib/python3.12/site-packages/sqlalchemy/engine/base.py", line 96, in __init__
    else engine.raw_connection()
         ^^^^^^^^^^^^^^^^^^^^^^^
  File "/home/airflow/.local/lib/python3.12/site-packages/sqlalchemy/engine/base.py", line 3404, in raw_connection
    return self._wrap_pool_connect(self.pool.connect, _connection)
           ^^^^^^^^^^^^^^^^^^^^^^^^^^^^^^^^^^^^^^^^^^^^^^^^^^^^^^^
  File "/home/airflow/.local/lib/python3.12/site-packages/sqlalchemy/engine/base.py", line 3374, in _wrap_pool_connect
    Connection._handle_dbapi_exception_noconnection(
  File "/home/airflow/.local/lib/python3.12/site-packages/sqlalchemy/engine/base.py", line 2208, in _handle_dbapi_exception_noconnection
    util.raise_(
  File "/home/airflow/.local/lib/python3.12/site-packages/sqlalchemy/util/compat.py", line 211, in raise_
    raise exception
  File "/home/airflow/.local/lib/python3.12/site-packages/sqlalchemy/engine/base.py", line 3371, in _wrap_pool_connect
    return fn()
           ^^^^
  File "/home/airflow/.local/lib/python3.12/site-packages/sqlalchemy/pool/base.py", line 327, in connect
    return _ConnectionFairy._checkout(self)
           ^^^^^^^^^^^^^^^^^^^^^^^^^^^^^^^^
  File "/home/airflow/.local/lib/python3.12/site-packages/sqlalchemy/pool/base.py", line 894, in _checkout
    fairy = _ConnectionRecord.checkout(pool)
            ^^^^^^^^^^^^^^^^^^^^^^^^^^^^^^^^
  File "/home/airflow/.local/lib/python3.12/site-packages/sqlalchemy/pool/base.py", line 497, in checkout
    with util.safe_reraise():
  File "/home/airflow/.local/lib/python3.12/site-packages/sqlalchemy/util/langhelpers.py", line 70, in __exit__
    compat.raise_(
  File "/home/airflow/.local/lib/python3.12/site-packages/sqlalchemy/util/compat.py", line 211, in raise_
    raise exception
  File "/home/airflow/.local/lib/python3.12/site-packages/sqlalchemy/pool/base.py", line 495, in checkout
    dbapi_connection = rec.get_connection()
                       ^^^^^^^^^^^^^^^^^^^^
  File "/home/airflow/.local/lib/python3.12/site-packages/sqlalchemy/pool/base.py", line 630, in get_connection
    self.__connect()
  File "/home/airflow/.local/lib/python3.12/site-packages/sqlalchemy/pool/base.py", line 690, in __connect
    with util.safe_reraise():
  File "/home/airflow/.local/lib/python3.12/site-packages/sqlalchemy/util/langhelpers.py", line 70, in __exit__
    compat.raise_(
  File "/home/airflow/.local/lib/python3.12/site-packages/sqlalchemy/util/compat.py", line 211, in raise_
    raise exception
  File "/home/airflow/.local/lib/python3.12/site-packages/sqlalchemy/pool/base.py", line 686, in __connect
    self.dbapi_connection = connection = pool._invoke_creator(self)
                                         ^^^^^^^^^^^^^^^^^^^^^^^^^^
  File "/home/airflow/.local/lib/python3.12/site-packages/sqlalchemy/engine/create.py", line 574, in connect
    return dialect.connect(*cargs, **cparams)
           ^^^^^^^^^^^^^^^^^^^^^^^^^^^^^^^^^^
  File "/home/airflow/.local/lib/python3.12/site-packages/sqlalchemy/engine/default.py", line 598, in connect
    return self.dbapi.connect(*cargs, **cparams)
           ^^^^^^^^^^^^^^^^^^^^^^^^^^^^^^^^^^^^^
  File "/home/airflow/.local/lib/python3.12/site-packages/psycopg2/__init__.py", line 122, in connect
    conn = _connect(dsn, connection_factory=connection_factory, **kwasync)
           ^^^^^^^^^^^^^^^^^^^^^^^^^^^^^^^^^^^^^^^^^^^^^^^^^^^^^^^^^^^^^^^
sqlalchemy.exc.OperationalError: (psycopg2.OperationalError) connection to server at "postgres" (172.18.0.3), port 5432 failed: Connection refused
	Is the server running on that host and accepting TCP/IP connections?

(Background on this error at: https://sqlalche.me/e/14/e3q8)
[2024-05-10T00:06:09.913+0000] {processor.py:161} INFO - Started process (PID=50) to work on /home/airflow/.local/lib/python3.12/site-packages/airflow/example_dags/example_sla_dag.py
[2024-05-10T00:06:09.920+0000] {processor.py:830} INFO - Processing file /home/airflow/.local/lib/python3.12/site-packages/airflow/example_dags/example_sla_dag.py for tasks to queue
[2024-05-10T00:06:09.943+0000] {logging_mixin.py:188} INFO - [2024-05-10T00:06:09.942+0000] {dagbag.py:545} INFO - Filling up the DagBag from /home/airflow/.local/lib/python3.12/site-packages/airflow/example_dags/example_sla_dag.py
[2024-05-10T00:06:09.990+0000] {processor.py:840} INFO - DAG(s) 'example_sla_dag' retrieved from /home/airflow/.local/lib/python3.12/site-packages/airflow/example_dags/example_sla_dag.py
[2024-05-10T00:06:10.086+0000] {logging_mixin.py:188} INFO - [2024-05-10T00:06:10.085+0000] {dag.py:3096} INFO - Sync 1 DAGs
[2024-05-10T00:06:10.227+0000] {logging_mixin.py:188} INFO - [2024-05-10T00:06:10.223+0000] {dag.py:3954} INFO - Setting next_dagrun for example_sla_dag to 2024-05-10 00:04:00+00:00, run_after=2024-05-10 00:06:00+00:00
[2024-05-10T00:06:10.358+0000] {processor.py:183} INFO - Processing /home/airflow/.local/lib/python3.12/site-packages/airflow/example_dags/example_sla_dag.py took 0.472 seconds
